Workbook

Sheet Summary
A1: LOB | B1: Campaign | C1: Corelation on SPD/CS | D1: Helpfullness Score | E1: Product Knowledge and Explanation | F1: Acknowledge & Empathize | G1: Transaction | H1: Language, Tone and Professionalism | I1: Compliance | J1: Listening & Understanding of Needs | K1: Count of HC <80 | L1: Count of HC >80-85 | M1: Count of HC > 85-90 | N1: Count of HC > 90-95 | O1: Count of HC > 95
A2: Auto | B2: D2C Fresh | C2: =Auto!AM2 -> 0.16779371 | D2: 86.53 | E2: =Auto!AD2 -> 0.1817589 | F2: =Auto!AE2 -> 0.18815421 | G2: =Auto!AG2 -> 0.16185167 | H2: =Auto!AH2 -> 0.071035431 | I2: =Auto!AI2 -> 0.10929378 | J2: =Auto!AJ2 -> 0.034063309 | K2: =COUNTIFS(Auto!$A:$A,"D2C",Auto!$L:$L,"L80") -> 2 | L2: =COUNTIFS(Auto!$A:$A,"D2C",Auto!$L:$L,"81-85") -> 26 | M2: =COUNTIFS(Auto!$A:$A,"D2C",Auto!$L:$L,"85-90") -> 73 | N2: =COUNTIFS(Auto!$A:$A,"D2C",Auto!$L:$L,"91-95") -> 7 | O2: =COUNTIFS(Auto!$A:$A,"D2C",Auto!$L:$L,"G95%") -> 0
B3: Winback | C3: =Auto!AM200 -> 0.28273593 | D3: 86.16 | E3: =Auto!AD200 -> 0.21980356 | F3: =Auto!AE200 -> 0.032911445 | G3: =Auto!AG200 -> 0.1444487 | H3: =Auto!AH200 -> 0.12116471 | I3: =Auto!AI200 -> -0.064285431 | J3: =Auto!AJ200 -> 0.21998985 | K3: =COUNTIFS(Auto!$A:$A,"Winback",Auto!$L:$L,"L80") -> 0 | L3: =COUNTIFS(Auto!$A:$A,"Winback",Auto!$L:$L,"81-85") -> 19 | M3: =COUNTIFS(Auto!$A:$A,"Winback",Auto!$L:$L,"85-90") -> 52 | N3: =COUNTIFS(Auto!$A:$A,"Winback",Auto!$L:$L,"91-95") -> 4 | O3: =COUNTIFS(Auto!$A:$A,"Winback",Auto!$L:$L,"G95%") -> 0
B4: WB Bike | C4: =Auto!AM282 -> 0.12886186 | D4: 86.36 | E4: =Auto!AD282 -> 0.10839409 | F4: =Auto!AE282 -> 0.26474339 | G4: =Auto!AG282 -> -0.046910174 | H4: =Auto!AH282 -> -0.12509037 | I4: =Auto!AI282 -> 0.35101525 | J4: =Auto!AJ282 -> -0.041271712 | K4: =COUNTIFS(Auto!$A:$A,"Winback - Bike",Auto!$L:$L,"L80") -> 0 | L4: =COUNTIFS(Auto!$A:$A,"Winback - Bike",Auto!$L:$L,"81-85") -> 9 | M4: =COUNTIFS(Auto!$A:$A,"Winback - Bike",Auto!$L:$L,"85-90") -> 17 | N4: =COUNTIFS(Auto!$A:$A,"Winback - Bike",Auto!$L:$L,"91-95") -> 0 | O4: =COUNTIFS(Auto!$A:$A,"Winback - Bike",Auto!$L:$L,"G95%") -> 0
B5: Renewal | C5: =Auto!AM171 -> 0.57206073 | D5: 86.62 | E5: =Auto!AD171 -> 0.5661099 | F5: =Auto!AE171 -> 0.53752358 | G5: =Auto!AG171 -> 0.48209282 | H5: =Auto!AH171 -> 0.38608582 | I5: =Auto!AI171 -> -0.36724225 | J5: =Auto!AJ171 -> 0.58830674 | K5: =COUNTIFS(Auto!$A:$A,"Renewal",Auto!$L:$L,"L80") -> 0 | L5: =COUNTIFS(Auto!$A:$A,"Renewal",Auto!$L:$L,"81-85") -> 10 | M5: =COUNTIFS(Auto!$A:$A,"Renewal",Auto!$L:$L,"85-90") -> 15 | N5: =COUNTIFS(Auto!$A:$A,"Renewal",Auto!$L:$L,"91-95") -> 0 | O5: =COUNTIFS(Auto!$A:$A,"Renewal",Auto!$L:$L,"G95%") -> 2
B6: New Car | C6: =Auto!AM130 -> -0.37359679 | D6: 88.44 | E6: =Auto!AD130 -> -0.50819772 | F6: =Auto!AE130 -> -0.2233132 | G6: =Auto!AG130 -> -0.15468556 | H6: =Auto!AH130 -> -0.22216079 | I6: =Auto!AI130 -> -0.22556161 | J6: =Auto!AJ130 -> -0.26436608 | K6: =COUNTIFS(Auto!$A:$A,"New Car",Auto!$L:$L,"L80") -> 0 | L6: =COUNTIFS(Auto!$A:$A,"New Car",Auto!$L:$L,"81-85") -> 0 | M6: =COUNTIFS(Auto!$A:$A,"New Car",Auto!$L:$L,"85-90") -> 34 | N6: =COUNTIFS(Auto!$A:$A,"New Car",Auto!$L:$L,"91-95") -> 3 | O6: =COUNTIFS(Auto!$A:$A,"New Car",Auto!$L:$L,"G95%") -> 2
B7: New Bike | C7: =Auto!AM113 -> 0.26480193 | D7: 87.29 | E7: =Auto!AD113 -> 0.39051485 | F7: =Auto!AE113 -> 0.085714598 | G7: =Auto!AG113 -> 0.072432395 | H7: =Auto!AH113 -> 0.1715217 | I7: =Auto!AI113 -> 0.20614758 | J7: =Auto!AJ113 -> 0.10397955 | K7: =COUNTIFS(Auto!$A:$A,"New Bike",Auto!$L:$L,"L80") -> 0 | L7: =COUNTIFS(Auto!$A:$A,"New Bike",Auto!$L:$L,"81-85") -> 4 | M7: =COUNTIFS(Auto!$A:$A,"New Bike",Auto!$L:$L,"85-90") -> 9 | N7: =COUNTIFS(Auto!$A:$A,"New Bike",Auto!$L:$L,"91-95") -> 1 | O7: =COUNTIFS(Auto!$A:$A,"New Bike",Auto!$L:$L,"G95%") -> 1
B8: Overall | C8: =Auto!AN2 -> 0.18424575 | D8: 86.73
A10: Health
B11: Mag7
A15: LOB | B15: Campaign | C15: Corelation on SPD/CS | D15: Helpfullness Score | F15: Acknowledge & Empathise | G15: Transaction | H15: Language, Tone and Professionalism | J15: Listening & Understanding Needs | K15: Count of HC <80 | L15: Count of HC >80-85 | M15: Count of HC > 85-90 | N15: Count of HC > 90-95 | O15: Count of HC > 95
A16: Life | B16: D2C Fresh | C16: =Life!M2 -> 0.34794863 | D16: 88.56 | F16: =Life!T2 -> 0.21901892 | G16: =Life!V2 -> 0.30753405 | H16: =Life!U2 -> 0.40176049 | J16: =Life!T2 -> 0.21901892 | K16: 0 | L16: 0 | M16: 10 | N16: 2 | O16: 0
B17: Renewal
A19: CS
B20: Batch 1
B21: Batch 2
B22: Inhouse
B23: Bhopal V
B24: Amristar V

Sheet Auto
A1: Campaign | B1: Team Leader | C1: Emp ID | D1: Advisor | E1: Mandays | F1: Total Attempted | G1: Total Connected | H1: Average of Talk_Duration | I1: Assisted Sales ( Last Connected Agent >=60secs) | J1: SPD/Agent | K1: Helpfullness Score | L1: Quality Bucket | M1: Product Knowledge and Explanation | N1: Acknowledge & Empathize | O1: Transaction & Resolution [3].percentage | P1: Transaction | Q1: Language, Tone and Professionalism | R1: Compliance | S1: Listening & Understanding of Needs | T1: % Escalations | U1: % of Followup | V1: Buy on Call | W1: NMI | X1: WOW | Y1: % Positive | Z1: Negative | AA1: % Neutral | AD1: Correlation | AE1: Correlation | AG1: Correlation | AH1: Correlation | AI1: Correlation | AJ1: Correlation | AM1: Correlation
A2: D2C | C2: IASPL26021 | D2: simran chauhan | E2: 24 | F2: 4764 | G2: 4566 | H2: 0.093113426 | I2: 58 | J2: =I2/E2 -> 2.4166667 | K2: 79.15 | L2: =IF(K2<80,"L80",IF(K2<=85,"81-85",IF(K2<=90,"85-90",IF(K2<=95,"91-95","G95%")))) -> L80 | M2: 68.71 | N2: 73.15 | P2: 82.15 | Q2: 88.49 | R2: 9.38 | S2: 86.88 | AD2: =CORREL(M2:M110,$J$2:$J$110) -> 0.1817589 | AE2: =CORREL(N2:N110,$J$2:$J$110) -> 0.18815421 | AG2: =CORREL(P2:P110,$J$2:$J$110) -> 0.16185167 | AH2: =CORREL(Q2:Q110,$J$2:$J$110) -> 0.071035431 | AI2: =CORREL(R2:R110,$J$2:$J$110) -> 0.10929378 | AJ2: =CORREL(S2:S110,$J$2:$J$110) -> 0.034063309 | AM2: =CORREL(K2:K109,J2:J109) -> 0.16779371 | AN2: =CORREL(J:J,K:K) -> 0.18424575
A3: D2C | C3: 22432 | D3: Snehal pawar | E3: 24 | F3: 5141 | G3: 4841 | H3: 0.13533565 | I3: 135 | J3: =I3/E3 -> 5.625 | K3: 79.83 | L3: =IF(K3<80,"L80",IF(K3<=85,"81-85",IF(K3<=90,"85-90",IF(K3<=95,"91-95","G95%")))) -> L80 | M3: 71.92 | N3: 72.84 | P3: 80.09 | Q3: 86.98 | R3: 10 | S3: 85.23 | U3: metaAttributes.positive_sentiment_count
A4: D2C | C4: IASPL26973 | D4: Sahil Afroze | E4: 18 | F4: 2976 | G4: 2893 | H4: 0.088159722 | I4: 37 | J4: =I4/E4 -> 2.0555556 | K4: 80.53 | L4: =IF(K4<80,"L80",IF(K4<=85,"81-85",IF(K4<=90,"85-90",IF(K4<=95,"91-95","G95%")))) -> 81-85 | M4: 73.13 | N4: 73.77 | P4: 82.18 | Q4: 86.96 | R4: 0 | S4: 87.4 | U4: metaAttributes.follow_up_required_count
A5: D2C | C5: IASPL23823 | D5: Himanshi Gupta | E5: 25 | F5: 4573 | G5: 4324 | H5: 0.11049769 | I5: 89 | J5: =I5/E5 -> 3.56 | K5: 82.25 | L5: =IF(K5<80,"L80",IF(K5<=85,"81-85",IF(K5<=90,"85-90",IF(K5<=95,"91-95","G95%")))) -> 81-85 | M5: 71.5 | N5: 77.72 | P5: 84.77 | Q5: 90.13 | R5: 0 | S5: 89.76 | U5: metaAttributes.unresolved_count
A6: D2C | C6: IASPL26341 | D6: Mohammed Amir Ahmed Taha | E6: 20 | F6: 2923 | G6: 2858 | H6: 0.071863426 | I6: 52 | J6: =I6/E6 -> 2.6 | K6: 82.28 | L6: =IF(K6<80,"L80",IF(K6<=85,"81-85",IF(K6<=90,"85-90",IF(K6<=95,"91-95","G95%")))) -> 81-85 | M6: 69.66 | N6: 75.9 | P6: 84.7 | Q6: 89.03 | R6: 0 | S6: 90.2 | U6: metaAttributes.partially_resolved_count
A7: D2C | C7: IASPL26463 | D7: Aakansha | E7: 26 | F7: 5075 | G7: 4855 | H7: 0.093599537 | I7: 71 | J7: =I7/E7 -> 2.7307692 | K7: 82.48 | L7: =IF(K7<80,"L80",IF(K7<=85,"81-85",IF(K7<=90,"85-90",IF(K7<=95,"91-95","G95%")))) -> 81-85 | M7: 72.1 | N7: 74.98 | P7: 85.39 | Q7: 91.53 | R7: 20 | S7: 89.7 | U7: metaAttributes.negative_sentiment_count | Y7: metaAttributes.non_material_interaction_count | Z7: metaAttributes.positive_intent_needs_follow_up_count | AA7: metaAttributes.will_buy_self_count | AB7: metaAttributes.payment_done_count | AC7: metaAttributes.not_interested_in_buying_count | AD7: metaAttributes.escalated_count
A8: D2C | C8: IASPL26057 | D8: Vishal Singh Chauhan | E8: 24 | F8: 3477 | G8: 3351 | H8: 0.074525463 | I8: 36 | J8: =I8/E8 -> 1.5 | K8: 82.64 | L8: =IF(K8<80,"L80",IF(K8<=85,"81-85",IF(K8<=90,"85-90",IF(K8<=95,"91-95","G95%")))) -> 81-85 | M8: 70.61 | N8: 75.96 | P8: 86.68 | Q8: 90.36 | R8: 0 | S8: 91.12 | U8: metaAttributes.neutral_sentiment_count | Y8: metaAttributes.non_material_interaction_count
A9: D2C | C9: IASPL14177 | D9: Mushtaq Ali | E9: 26 | F9: 2809 | G9: 2602 | H9: 0.16751157 | I9: 200 | J9: =I9/E9 -> 7.6923077 | K9: 82.86 | L9: =IF(K9<80,"L80",IF(K9<=85,"81-85",IF(K9<=90,"85-90",IF(K9<=95,"91-95","G95%")))) -> 81-85 | M9: 77.29 | N9: 76.17 | P9: 84.72 | Q9: 89.01 | R9: 12.5 | S9: 87.57 | U9: metaAttributes.threatened_to_escalate_count | Y9: metaAttributes.positive_intent_needs_follow_up_count
A10: D2C | C10: 22433 | D10: Munirul Hasan Momin | E10: 23 | F10: 4186 | G10: 3992 | H10: 0.093240741 | I10: 74 | J10: =I10/E10 -> 3.2173913 | K10: 82.95 | L10: =IF(K10<80,"L80",IF(K10<=85,"81-85",IF(K10<=90,"85-90",IF(K10<=95,"91-95","G95%")))) -> 81-85 | M10: 74.86 | N10: 74.48 | P10: 85.67 | Q10: 89.1 | R10: 0 | S10: 89.89 | U10: metaAttributes.resolved_count | Y10: metaAttributes.will_buy_self_count
A11: D2C | C11: IASPL15100 | D11: Rahul R | E11: 26 | F11: 4774 | G11: 4549 | H11: 0.13841435 | I11: 103 | J11: =I11/E11 -> 3.9615385 | K11: 83.07 | L11: =IF(K11<80,"L80",IF(K11<=85,"81-85",IF(K11<=90,"85-90",IF(K11<=95,"91-95","G95%")))) -> 81-85 | M11: 77.12 | N11: 77.64 | P11: 85.07 | Q11: 88.38 | R11: 15 | S11: 89.6 | Y11: metaAttributes.payment_done_count
A12: D2C | C12: IASPL14235 | D12: Anush Kumar K | E12: 26 | F12: 3374 | G12: 3211 | H12: 0.12240741 | I12: 229 | J12: =I12/E12 -> 8.8076923 | K12: 83.18 | L12: =IF(K12<80,"L80",IF(K12<=85,"81-85",IF(K12<=90,"85-90",IF(K12<=95,"91-95","G95%")))) -> 81-85 | M12: 73.47 | N12: 77.12 | P12: 86.35 | Q12: 89.89 | R12: 7.14 | S12: 89.49 | Y12: metaAttributes.not_interested_in_buying_count
A13: D2C | C13: IASPL14182 | D13: Roza Rashid Sanadi | E13: 25 | F13: 5754 | G13: 5518 | H13: 0.13040509 | I13: 100 | J13: =I13/E13 -> 4 | K13: 83.19 | L13: =IF(K13<80,"L80",IF(K13<=85,"81-85",IF(K13<=90,"85-90",IF(K13<=95,"91-95","G95%")))) -> 81-85 | M13: 77.53 | N13: 77.64 | P13: 83.9 | Q13: 87.52 | R13: 15.38 | S13: 88.75 | Y13: metaAttributes.escalated_count
A14: D2C | C14: IASPL23828 | D14: Riya | E14: 26 | F14: 6401 | G14: 5757 | H14: 0.12524306 | I14: 104 | J14: =I14/E14 -> 4 | K14: 83.2 | L14: =IF(K14<80,"L80",IF(K14<=85,"81-85",IF(K14<=90,"85-90",IF(K14<=95,"91-95","G95%")))) -> 81-85 | M14: 72.62 | N14: 78.63 | P14: 86.32 | Q14: 91.07 | R14: 5 | S14: 90.61
A15: D2C | C15: 22103 | D15: Vruddhi Karaia | E15: 25 | F15: 4851 | G15: 4548 | H15: 0.13167824 | I15: 249 | J15: =I15/E15 -> 9.96 | K15: 83.45 | L15: =IF(K15<80,"L80",IF(K15<=85,"81-85",IF(K15<=90,"85-90",IF(K15<=95,"91-95","G95%")))) -> 81-85 | M15: 77.31 | N15: 77.76 | P15: 84.61 | Q15: 88.9 | R15: 0 | S15: 88.94
A16: D2C | C16: IASPL28157 | D16: Saqiya Anjum Shaikh | E16: 25 | F16: 4572 | G16: 4267 | H16: 0.165 | I16: 162 | J16: =I16/E16 -> 6.48 | K16: 83.48 | L16: =IF(K16<80,"L80",IF(K16<=85,"81-85",IF(K16<=90,"85-90",IF(K16<=95,"91-95","G95%")))) -> 81-85 | M16: 73.68 | N16: 78.6 | P16: 86.89 | Q16: 90.15 | R16: 16.67 | S16: 90.13
A17: D2C | C17: 60258 | D17: Irfan Ahamad | E17: 25 | F17: 3662 | G17: 3412 | H17: 0.14709491 | I17: 224 | J17: =I17/E17 -> 8.96 | K17: 83.48 | L17: =IF(K17<80,"L80",IF(K17<=85,"81-85",IF(K17<=90,"85-90",IF(K17<=95,"91-95","G95%")))) -> 81-85 | M17: 74.45 | N17: 76.03 | P17: 86.14 | Q17: 89.44 | R17: 12.5 | S17: 90.1
A18: D2C | C18: IASPL20891 | D18: Sengmai Sinpho | E18: 24 | F18: 4181 | G18: 3946 | H18: 0.16077546 | I18: 101 | J18: =I18/E18 -> 4.2083333 | K18: 83.52 | L18: =IF(K18<80,"L80",IF(K18<=85,"81-85",IF(K18<=90,"85-90",IF(K18<=95,"91-95","G95%")))) -> 81-85 | M18: 78.13 | N18: 78.68 | P18: 85.04 | Q18: 88.2 | R18: 25 | S18: 88.12
A19: D2C | C19: IASPL23821 | D19: Sambhuvey Mishra | E19: 25 | F19: 6542 | G19: 5991 | H19: 0.12166667 | I19: 114 | J19: =I19/E19 -> 4.56 | K19: 83.66 | L19: =IF(K19<80,"L80",IF(K19<=85,"81-85",IF(K19<=90,"85-90",IF(K19<=95,"91-95","G95%")))) -> 81-85 | M19: 72.81 | N19: 80.05 | P19: 85.8 | Q19: 90.19 | R19: 17.86 | S19: 89.26
A20: D2C | C20: IASPL14383 | D20: Shruti S Rangari | E20: 26 | F20: 4818 | G20: 4506 | H20: 0.14601852 | I20: 120 | J20: =I20/E20 -> 4.6153846 | K20: 84 | L20: =IF(K20<80,"L80",IF(K20<=85,"81-85",IF(K20<=90,"85-90",IF(K20<=95,"91-95","G95%")))) -> 81-85 | M20: 77.38 | N20: 80.5 | P20: 86.61 | Q20: 88.91 | R20: 20 | S20: 90.41
A21: D2C | C21: 60668 | D21: Safiya Baig | E21: 14 | F21: 3065 | G21: 3022 | H21: 0.073506944 | I21: 61 | J21: =I21/E21 -> 4.3571429 | K21: 84 | L21: =IF(K21<80,"L80",IF(K21<=85,"81-85",IF(K21<=90,"85-90",IF(K21<=95,"91-95","G95%")))) -> 81-85 | M21: 73.38 | N21: 83.04 | P21: 86.56 | Q21: 89.8 | R21: 0 | S21: 91.61
A22: D2C | C22: IASPL25807 | D22: Mansoor Ahmed | E22: 23 | F22: 2569 | G22: 2544 | H22: 0.06525463 | I22: 30 | J22: =I22/E22 -> 1.3043478 | K22: 84.04 | L22: =IF(K22<80,"L80",IF(K22<=85,"81-85",IF(K22<=90,"85-90",IF(K22<=95,"91-95","G95%")))) -> 81-85 | M22: 78.39 | N22: 78.6 | P22: 84.4 | Q22: 88.36 | R22: 0 | S22: 90.24
A23: D2C | C23: IASPL14397 | D23: Hajira Z | E23: 24 | F23: 4520 | G23: 4375 | H23: 0.10440972 | I23: 150 | J23: =I23/E23 -> 6.25 | K23: 84.05 | L23: =IF(K23<80,"L80",IF(K23<=85,"81-85",IF(K23<=90,"85-90",IF(K23<=95,"91-95","G95%")))) -> 81-85 | M23: 75.87 | N23: 78.73 | P23: 85.07 | Q23: 89.85 | R23: 25 | S23: 88.64
A24: D2C | C24: IASPL21500 | D24: Sharana Basaveshwar | E24: 23 | F24: 3954 | G24: 3806 | H24: 0.15423611 | I24: 147 | J24: =I24/E24 -> 6.3913043 | K24: 84.16 | L24: =IF(K24<80,"L80",IF(K24<=85,"81-85",IF(K24<=90,"85-90",IF(K24<=95,"91-95","G95%")))) -> 81-85 | M24: 76.26 | N24: 77.93 | P24: 86.33 | Q24: 90.05 | R24: 3.57 | S24: 91.37
A25: D2C | C25: IASPL28985 | D25: Sufiya parveez | E25: 26 | F25: 4269 | G25: 4086 | H25: 0.1121875 | I25: 57 | J25: =I25/E25 -> 2.1923077 | K25: 84.32 | L25: =IF(K25<80,"L80",IF(K25<=85,"81-85",IF(K25<=90,"85-90",IF(K25<=95,"91-95","G95%")))) -> 81-85 | M25: 79.58 | N25: 78.5 | P25: 86.25 | Q25: 88.66 | R25: 17.5 | S25: 88.81
A26: D2C | C26: 22294 | D26: Insha Shaikh | E26: 24 | F26: 4047 | G26: 3667 | H26: 0.12883102 | I26: 71 | J26: =I26/E26 -> 2.9583333 | K26: 84.55 | L26: =IF(K26<80,"L80",IF(K26<=85,"81-85",IF(K26<=90,"85-90",IF(K26<=95,"91-95","G95%")))) -> 81-85 | M26: 78.64 | N26: 79.8 | P26: 85.95 | Q26: 89.61 | R26: 24.24 | S26: 90.12
A27: D2C | C27: 22381 | D27: Ayesha Patel | E27: 21 | F27: 2729 | G27: 2570 | H27: 0.077106481 | I27: 38 | J27: =I27/E27 -> 1.8095238 | K27: 84.57 | L27: =IF(K27<80,"L80",IF(K27<=85,"81-85",IF(K27<=90,"85-90",IF(K27<=95,"91-95","G95%")))) -> 81-85 | M27: 80.1 | N27: 79.05 | P27: 85.02 | Q27: 88.01 | R27: 20 | S27: 89.9
A28: D2C | C28: 22479 | D28: Aditya Harchande | E28: 24 | F28: 3589 | G28: 3356 | H28: 0.11055556 | I28: 66 | J28: =I28/E28 -> 2.75 | K28: 84.59 | L28: =IF(K28<80,"L80",IF(K28<=85,"81-85",IF(K28<=90,"85-90",IF(K28<=95,"91-95","G95%")))) -> 81-85 | M28: 76.89 | N28: 77.32 | P28: 87.4 | Q28: 91.28 | R28: 0 | S28: 91.55
A29: D2C | C29: IASPL28981 | D29: Meher banu | E29: 24 | F29: 4080 | G29: 3824 | H29: 0.12496528 | I29: 63 | J29: =I29/E29 -> 2.625 | K29: 84.74 | L29: =IF(K29<80,"L80",IF(K29<=85,"81-85",IF(K29<=90,"85-90",IF(K29<=95,"91-95","G95%")))) -> 81-85 | M29: 75.6 | N29: 81.71 | P29: 87.38 | Q29: 90.74 | R29: 17.19 | S29: 90.89
A30: D2C | C30: 22070 | D30: Yayati Nighojakar | E30: 28 | F30: 3880 | G30: 3664 | H30: 0.10827546 | I30: 188 | J30: =I30/E30 -> 6.7142857 | K30: 85.19 | L30: =IF(K30<80,"L80",IF(K30<=85,"81-85",IF(K30<=90,"85-90",IF(K30<=95,"91-95","G95%")))) -> 85-90 | M30: 78.68 | N30: 78.52 | P30: 86.28 | Q30: 90.07 | R30: 25 | S30: 90.77
A31: D2C | C31: IASPL26294 | D31: Kumud Chaudhary | E31: 25 | F31: 4355 | G31: 4049 | H31: 0.096273148 | I31: 59 | J31: =I31/E31 -> 2.36 | K31: 85.32 | L31: =IF(K31<80,"L80",IF(K31<=85,"81-85",IF(K31<=90,"85-90",IF(K31<=95,"91-95","G95%")))) -> 85-90 | M31: 79.43 | N31: 75.8 | P31: 87.52 | Q31: 90.15 | R31: 18.75 | S31: 90.89
A32: D2C | C32: 21635 | D32: Mayuri Pardeshi | E32: 26 | F32: 4727 | G32: 4423 | H32: 0.14814815 | I32: 241 | J32: =I32/E32 -> 9.2692308 | K32: 85.45 | L32: =IF(K32<80,"L80",IF(K32<=85,"81-85",IF(K32<=90,"85-90",IF(K32<=95,"91-95","G95%")))) -> 85-90 | M32: 77.69 | N32: 82.82 | P32: 87.32 | Q32: 90.03 | R32: 20.45 | S32: 91.54
A33: D2C | C33: IASPL24060 | D33: Surya K | E33: 26 | F33: 3993 | G33: 3830 | H33: 0.10415509 | I33: 73 | J33: =I33/E33 -> 2.8076923 | K33: 85.52 | L33: =IF(K33<80,"L80",IF(K33<=85,"81-85",IF(K33<=90,"85-90",IF(K33<=95,"91-95","G95%")))) -> 85-90 | M33: 76.38 | N33: 83.59 | P33: 86.85 | Q33: 90.12 | R33: 0 | S33: 91.36
A34: D2C | C34: 60667 | D34: Shambhu Das | E34: 27 | F34: 4860 | G34: 4552 | H34: 0.099050926 | I34: 63 | J34: =I34/E34 -> 2.3333333 | K34: 85.78 | L34: =IF(K34<80,"L80",IF(K34<=85,"81-85",IF(K34<=90,"85-90",IF(K34<=95,"91-95","G95%")))) -> 85-90 | M34: 77.59 | N34: 81.27 | P34: 88.14 | Q34: 91 | R34: 20.83 | S34: 91.52
A35: D2C | C35: IASPL26461 | D35: Farhan khan | E35: 20 | F35: 3172 | G35: 3013 | H35: 0.092233796 | I35: 55 | J35: =I35/E35 -> 2.75 | K35: 85.81 | L35: =IF(K35<80,"L80",IF(K35<=85,"81-85",IF(K35<=90,"85-90",IF(K35<=95,"91-95","G95%")))) -> 85-90 | M35: 76.91 | N35: 79.59 | P35: 89.1 | Q35: 91.75 | R35: 0 | S35: 92.51
A36: D2C | C36: IASPL26056 | D36: Pankaj kumar | E36: 19 | F36: 3001 | G36: 2847 | H36: 0.10116898 | I36: 46 | J36: =I36/E36 -> 2.4210526 | K36: 85.85 | L36: =IF(K36<80,"L80",IF(K36<=85,"81-85",IF(K36<=90,"85-90",IF(K36<=95,"91-95","G95%")))) -> 85-90 | M36: 76.84 | N36: 82.41 | P36: 88.5 | Q36: 91.66 | S36: 91.69
A37: D2C | C37: IASPL25503 | D37: Ayush Thapa | E37: 25 | F37: 4268 | G37: 4096 | H37: 0.089479167 | I37: 68 | J37: =I37/E37 -> 2.72 | K37: 85.86 | L37: =IF(K37<80,"L80",IF(K37<=85,"81-85",IF(K37<=90,"85-90",IF(K37<=95,"91-95","G95%")))) -> 85-90 | M37: 75.68 | N37: 80.56 | P37: 90.45 | Q37: 91.7 | R37: 4.17 | S37: 92.73
A38: D2C | C38: 22488 | D38: Sunita Jadhav | E38: 26 | F38: 3533 | G38: 2875 | H38: 0.1621875 | I38: 59 | J38: =I38/E38 -> 2.2692308 | K38: 85.91 | L38: =IF(K38<80,"L80",IF(K38<=85,"81-85",IF(K38<=90,"85-90",IF(K38<=95,"91-95","G95%")))) -> 85-90 | M38: 79.75 | N38: 82.05 | P38: 87.73 | Q38: 90.06 | R38: 18.18 | S38: 90.34
A39: D2C | C39: IASPL28711 | D39: Faizan Khan | E39: 26 | F39: 4348 | G39: 4103 | H39: 0.10092593 | I39: 64 | J39: =I39/E39 -> 2.4615385 | K39: 86.07 | L39: =IF(K39<80,"L80",IF(K39<=85,"81-85",IF(K39<=90,"85-90",IF(K39<=95,"91-95","G95%")))) -> 85-90 | M39: 78.72 | N39: 81.76 | P39: 87.84 | Q39: 91.37 | R39: 0 | S39: 92.14
A40: D2C | C40: IASPL29015 | D40: Shabaaz ahmed | E40: 25 | F40: 3175 | G40: 2974 | H40: 0.099328704 | I40: 64 | J40: =I40/E40 -> 2.56 | K40: 86.08 | L40: =IF(K40<80,"L80",IF(K40<=85,"81-85",IF(K40<=90,"85-90",IF(K40<=95,"91-95","G95%")))) -> 85-90 | M40: 77.42 | N40: 80.96 | P40: 88.71 | Q40: 91.52 | R40: 0 | S40: 93.13
...

Sheet Agent Index
B1: email ID | C1: Agent Name | D1: LOB
B2: haseeb.rehaman_scale_blr@acko.com | C2: Haseeb Ur Rehaman | D2: Existing - Mag7 New Batch New Advisor
B3: saravanan.nadar_scale_blr@acko.com | C3: Saravanan Nadar | D3: Existing - Mag7 New Batch New Advisor
B4: shaik.mohammed_scale_blr@acko.com | C4: Alfiya | D4: Existing - Mag7 New Batch New Advisor
B5: alfiya_scale_blr@acko.com | C5: Mohammed Suhail | D5: Existing - Mag7 New Batch Old Advisor
B6: mahalakshmi.kn_scale_blr@acko.com | C6: Mahalakshmi K N | D6: Existing - Mag7 New Batch Old Advisor
B7: ramya.m_scale_blr@acko.com | C7: M Ramya Priya | D7: Existing - Mag7 New Batch Old Advisor
B8: sufiya.annum_scale_blr@acko.com | C8: Sufiya Annum | D8: Existing - Mag7 New Batch Old Advisor
B9: vikram.singh1_scale_blr@acko.com | C9: Vikram Singh | D9: Existing - Mag7 New Batch Old Advisor
B10: deepak.kp_scale_blr@acko.com | C10: Deepak Singh K P | D10: Existing - Mag7 Pilot
B11: misba.azhar@acko.tech | C11: Misba Azhar | D11: Existing - Mag7 Pilot
B12: mohammed.suhail@acko.tech | C12: Mohammed Suhail | D12: Existing - Mag7 Pilot
... B57: subhash.das_scale_blr@acko.com | C57: Subhash Chandra Das | D57: Winback
B58: attikka.danish_scale_blr@acko.com | D58: Renewals
B59: bojamma.ka_scale_blr@acko.com | D59: Renewals
B60: mashood.khan_scale_blr@acko.com | D60: Renewals
B61: nazimulla.khan_scale_blr@acko.com | D61: Renewals

Sheet Health
A1: Campaign | B1: Team Leader | C1: ECN | D1: Advisor | E1: Mandays | F1: Total Attempted | G1: Total Connected | H1: Avg Talk time per day | I1: Assisted Sales ( Highest TT >5min) | J1: SPD/Agent | K1: Quality Score | L1: Listening & Understanding Needs | M1: Product Knowledge and Explanation | N1: Transaction | O1: Acknowledge & Empathise | P1: Language, Tone and Professionalism | Q1: Positive | R1: Negative | S1: Neutral | T1: .escalated | U1: .not_interested_in_buying | V1: .payment_done | W1: .will_buy_self | X1: .positive_intent_needs_follow_up | Y1: .non_material_interaction | Z1: .follow_up_required | AA1: .unresolved | AB1: .partially_resolved | AC1: .resolved | AD1: .threatened_to_escalate | AF1: Correlation | AG1: Correlation | AH1: Correlation | AI1: Correlation | AJ1: Correlation | AK1: Correlation | AL1: Correlation | AM1: Correlation | AN1: Correlation | AO1: Correlation | AP1: Correlation | AQ1: Correlation | AR1: Correlation | AS1: Correlation | AT1: Correlation | AU1: Correlation | AV1: Correlation | AW1: Correlation | AX1: Correlation | AY1: Correlation
A2: Inbound | B2: Beena PG | C2: S16447 | D2: Abhishek Chandra | E2: 25 | F2: 1390 | G2: 785 | H2: 0.15332176 | I2: 42 | J2: 1.68 | K2: 90.58 | L2: 90.65 | M2: 88.39 | N2: 89.96 | O2: 90.15 | P2: 94.15 | Q2: 0.1703 | R2: 0.038 | S2: 0.7917 | T2: 0.0054 | U2: 0.0725 | V2: 0.0435 | W2: 0.0725 | X2: 0.6014 | Y2: 0.0797 | Z2: 0.0435 | AA2: 0.0163 | AB2: 0.0072 | AC2: 0.0471 | AD2: 0.0054 | AF2: =CORREL($J$2:$J$7,K2:K7) -> -0.48977773 | AG2: =CORREL($J$2:$J$7,L2:L7) -> -0.43943158 | AH2: =CORREL($J$2:$J$7,M2:M7) -> -0.5316748 | AI2: =CORREL($J$2:$J$7,N2:N7) -> -0.42596535 | AJ2: =CORREL($J$2:$J$7,O2:O7) -> -0.22137335 | AK2: =CORREL($J$2:$J$7,P2:P7) -> -0.47818688 | AL2: =CORREL($J$2:$J$7,Q2:Q7) -> 0.30923163 | AM2: =CORREL($J$2:$J$7,R2:R7) -> 0.017855141 | ... AY2: =CORREL($J$2:$J$7,AD2:AD7) -> 0.19441823
A3: Inbound | B3: Beena PG | C3: S12777 | D3: Bellary Jaffer Sadiq | E3: 25 | F3: 1478 | G3: 775 | H3: 0.13321759 | I3: 44 | J3: 1.76 | K3: 88.38 | L3: 89.4 | M3: 85.44 | N3: 87.28 | O3: 88.59 | P3: 91.93 | Q3: 0.1486 | R3: 0.044 | S3: 0.8073 | T3: 0.011 | U3: 0.0532 | V3: 0.022 | W3: 0.0624 | X3: 0.6771 | Y3: 0.055 | Z3: 0.0404 | AA3: 0.0165 | AB3: 0.0055 | AC3: 0.044 | AD3: 0.0037
A4: Inbound | B4: Beena PG | C4: S13372 | D4: Muzammil Khan | E4: 22 | F4: 904 | G4: 703 | H4: 0.1478588 | I4: 36 | J4: 1.6363636 | K4: 89.99 | L4: 90.5 | M4: 87.06 | N4: 89.58 | O4: 89.74 | P4: 93.69 | Q4: 0.2283 | R4: 0.0465 | S4: 0.7252 | T4: 0.0127 | U4: 0.0677 | V4: 0.0592 | W4: 0.0761 | X4: 0.5814 | Y4: 0.0825 | Z4: 0.0507 | AA4: 0.0127 | AB4: 0.0021 | AC4: 0.0529 | AD4: 0.0063
A5: Inbound | B5: Beena PG | C5: S13217 | D5: Syed Shahbaz | E5: 26 | F5: 1745 | G5: 925 | H5: 0.13175926 | I5: 44 | J5: 1.6923077 | K5: 88.97 | L5: 89.29 | M5: 86.87 | N5: 87.55 | O5: 89.13 | P5: 92.54 | Q5: 0.1921 | R5: 0.0377 | S5: 0.7702 | T5: 0.0206 | U5: 0.0429 | V5: 0.036 | W5: 0.0652 | X5: 0.6672 | Y5: 0.0583 | Z5: 0.024 | AA5: 0.024 | AB5: 0.0086 | AC5: 0.0497 | AD5: 0.0051
A6: Inbound | B6: Beena PG | C6: S19405 | D6: Nitish Kumar Singh | E6: 25 | F6: 1249 | G6: 728 | H6: 0.12746528 | I6: 35 | J6: 1.4 | K6: 90.36 | L6: 90.37 | M6: 88.2 | N6: 89.59 | O6: 90.45 | P6: 93.74 | Q6: 0.1402 | R6: 0.0392 | S6: 0.8206 | T6: 0.0186 | U6: 0.0784 | V6: 0.0206 | W6: 0.1031 | X6: 0.5814 | Y6: 0.0412 | Z6: 0.0577 | AA6: 0.0165 | AB6: 0.0124 | AC6: 0.0598 | AD6: 0.0041
A7: Inbound | B7: Beena PG | C7: S12780 | D7: Rajesh Das | E7: 27 | F7: 1151 | G7: 944 | H7: 0.14443287 | I7: 42 | J7: 1.5555556 | K7: 88.97 | L7: 89.89 | M7: 86.47 | N7: 87.78 | O7: 87.18 | P7: 92.87 | Q7: 0.1669 | R7: 0.0477 | S7: 0.7854 | T7: 0.0168 | U7: 0.0743 | V7: 0.0351 | W7: 0.0996 | X7: 0.5877 | Y7: 0.0533 | Z7: 0.0491 | AA7: 0.0084 | AB7: 0.007 | AC7: 0.0631 | AD7: 0.0042
A9: Campaign | B9: TL | C9: ECN | D9: Advisor | E9: Mandays | F9: Total Attempted | G9: Total Connected | H9: Avg Talk time per day | I9: Assisted Sales ( Highest TT >5min) | J9: SPD/Agent | K9: Quality Score | L9: Listening & Understanding Needs | M9: Product Knowledge and Explanation | N9: Transaction | O9: Acknowledge & Empathise | P9: Language, Tone and Professionalism | Q9: Positive | R9: Negative | S9: Neutral | T9: .escalated | U9: .not_interested_in_buying | V9: .payment_done | W9: .will_buy_self | X9: .positive_intent_needs_follow_up | Y9: .non_material_interaction | Z9: .follow_up_required | AA9: .unresolved | AB9: .partially_resolved | AC9: .resolved | AD9: .threatened_to_escalate | AF9: Correlation | AG9: Correlation | AH9: Correlation | AI9: Correlation | AJ9: Correlation | AK9: Correlation | AL9: Correlation | AM9: Correlation | AN9: Correlation | AO9: Correlation | AP9: Correlation | AQ9: Correlation | AR9: Correlation | AS9: Correlation | AT9: Correlation | AU9: Correlation | AV9: Correlation | AW9: Correlation | AX9: Correlation | AY9: Correlation
A10: MAG7 | B10: Vikram Kumar majhi | C10: S16999 | D10: Sufiya Annum | E10: 23 | F10: 2245 | G10: 1793 | H10: 0.1287037 | I10: 61 | J10: 2.6521739 | K10: 89.61 | L10: 90.08 | M10: 85.34 | N10: 89.81 | O10: 90.63 | P10: 93.33 | Q10: 0.2454 | R10: 0.0093 | S10: 0.7454 | T10: 0 | U10: 0.044 | V10: 0.0579 | W10: 0.0671 | X10: 0.7593 | Y10: 0.0231 | Z10: 0.0185 | AA10: 0.0023 | AB10: 0 | AC10: 0.0185 | AD10: 0 | AF10: =CORREL($J$10:$J$22,K10:K22) -> 0.53112848 | AG10: =CORREL($J$10:$J$22,L10:L22) -> 0.38331508 | AH10: =CORREL($J$10:$J$22,M10:M22) -> 0.069412289 | AI10: =CORREL($J$10:$J$22,N10:N22) -> 0.45010613 | AJ10: =CORREL($J$10:$J$22,O10:O22) -> 0.62031971 | AK10: =CORREL($J$10:$J$22,P10:P22) -> 0.52041948 | AL10: =CORREL($J$10:$J$22,Q10:Q22) -> 0.49220487 | AM10: =CORREL($J$10:$J$22,R10:R22) -> -0.19715119 | ... AY10: =CORREL($J$10:$J$22,AD10:AD22) -> 0.17581158
A11: MAG7 | B11: Vikram Kumar majhi | C11: S17927 | D11: Vikram Singh | E11: 25 | F11: 1943 | G11: 1771 | H11: 0.17021991 | I11: 46 | J11: 1.84 | K11: 90.47 | L11: 90.86 | M11: 87.52 | N11: 91.63 | O11: 88.48 | P11: 93.85 | Q11: 0.178 | R11: 0.0186 | S11: 0.8034 | T11: 0.0051 | U11: 0.0797 | V11: 0.0271 | W11: 0.0525 | X11: 0.7237 | Y11: 0.0288 | Z11: 0.0458 | AA11: 0.0034 | AB11: 0.0034 | AC11: 0.0203 | AD11: 0
A12: MAG7 | B12: Vikram Kumar majhi | C12: S17590 | D12: Mahalakshmi K N | E12: 24 | F12: 2508 | G12: 1994 | H12: 0.15563657 | I12: 48 | J12: 2 | K12: 90.29 | L12: 90.09 | M12: 88.3 | N12: 90.09 | O12: 89.71 | P12: 93.49 | Q12: 0.1818 | R12: 0 | S12: 0.8182 | T12: 0 | U12: 0.0634 | V12: 0.0444 | W12: 0.0803 | X12: 0.6913 | Y12: 0.0529 | Z12: 0.0359 | AA12: 0.0085 | AB12: 0 | AC12: 0.0169 | AD12: 0
A13: MAG7 | B13: Geetha R | C13: AT1071 | D13: Mohammed Suhail | E13: 24 | F13: 2885 | G13: 1922 | H13: 0.12883102 | I13: 53 | J13: 2.2083333 | K13: 89.95 | L13: 87.29 | M13: 85.98 | N13: 87.39 | O13: 88.18 | P13: 93.1 | Q13: 0.1289 | R13: 0.0264 | S13: 0.8447 | T13: 0.0062 | U13: 0.0932 | V13: 0.0186 | W13: 0.0714 | X13: 0.6941 | Y13: 0.0233 | Z13: 0.0606 | AA13: 0.0093 | AB13: 0.0016 | AC13: 0.014 | AD13: 0.0062
A14: MAG7 | B14: Vikram Kumar majhi | C14: S24543 | D14: Saravanan Nadar | E14: 27 | F14: 3352 | G14: 2370 | H14: 0.17875 | I14: 49 | J14: 1.8148148 | K14: 87.64 | L14: 88.08 | M14: 85.51 | N14: 87.99 | O14: 86.17 | P14: 90.6 | Q14: 0.1479 | R14: 0.0199 | S14: 0.8321 | T14: 0.0028 | U14: 0.0811 | V14: 0.0228 | W14: 0.0541 | X14: 0.6885 | Y14: 0.0356 | Z14: 0.0569 | AA14: 0.0071 | AB14: 0.0043 | AC14: 0.0313 | AD14: 0.0028
A15: MAG7 | B15: Geetha R | C15: S17920 | D15: Deepak Singh K P | E15: 25 | F15: 2310 | G15: 2135 | H15: 0.14381944 | I15: 47 | J15: 1.88 | K15: 89.11 | L15: 88.95 | M15: 86.97 | N15: 88.93 | O15: 88.84 | P15: 92.36 | Q15: 0.1764 | R15: 0.0216 | S15: 0.802 | T15: 0 | U15: 0.0832 | V15: 0.02 | W15: 0.0483 | X15: 0.7255 | Y15: 0.0682 | Z15: 0.025 | AA15: 0.0033 | AB15: 0.005 | AC15: 0.0166 | AD15: 0
A16: MAG7 | B16: Geetha R | C16: AT1065 | D16: Sooraj Sashidharan | E16: 25 | F16: 3079 | G16: 1864 | H16: 0.19197917 | I16: 30 | J16: 1.2 | K16: 89.94 | L16: 89.78 | M16: 88.29 | N16: 89.74 | O16: 88.77 | P16: 93.26 | Q16: 0.1758 | R16: 0.0133 | S16: 0.8109 | T16: 0.0017 | U16: 0.0531 | V16: 0.0249 | W16: 0.0398 | X16: 0.7231 | Y16: 0.063 | Z16: 0.0514 | AA16: 0.0066 | AB16: 0.0017 | AC16: 0.0332 | AD16: 0
A17: MAG7 | B17: Vikram Kumar majhi | C17: S18928 | D17: M Ramya Priya | E17: 24 | F17: 3609 | G17: 2546 | H17: 0.13796296 | I17: 48 | J17: 2 | K17: 87.72 | L17: 87.47 | M17: 85.18 | N17: 86.54 | O17: 88.19 | P17: 92.12 | Q17: 0.1648 | R17: 0.0165 | S17: 0.8187 | T17: 0.0018 | U17: 0.0806 | V17: 0.0348 | W17: 0.044 | X17: 0.7289 | Y17: 0.0311 | Z17: 0.0458 | AA17: 0.0037 | AB17: 0.0037 | AC17: 0.0256 | AD17: 0.0037
A18: MAG7 | B18: Geetha R | C18: S12770 | D18: Alfiya | E18: 25 | F18: 3911 | G18: 2908 | H18: 0.15501157 | I18: 39 | J18: 1.56 | K18: 88.27 | L18: 86.67 | M18: 85.45 | N18: 86.48 | O18: 85.81 | P18: 92.09 | Q18: 0.1173 | R18: 0.0403 | S18: 0.8424 | T18: 0.0053 | U18: 0.0718 | V18: 0.0193 | W18: 0.0473 | X18: 0.627 | Y18: 0.0963 | Z18: 0.0438 | AA18: 0.0263 | AB18: 0.0035 | AC18: 0.0333 | AD18: 0.0053
A19: MAG7 | B19: Geetha R | C19: AT1060 | D19: Misba Azhar | E19: 23 | F19: 2740 | G19: 1934 | H19: 0.12099537 | I19: 24 | J19: 1.0434783 | K19: 85.71 | L19: 84.9 | M19: 83.78 | N19: 84.78 | O19: 85.59 | P19: 90.07 | Q19: 0.0874 | R19: 0.0175 | S19: 0.8951 | T19: 0.0019 | U19: 0.1029 | V19: 0.0058 | W19: 0.0835 | X19: 0.6233 | Y19: 0.0388 | Z19: 0.068 | AA19: 0.0155 | AB19: 0.0019 | AC19: 0.0408 | AD19: 0
A20: MAG7 | B20: Geetha R | C20: AT1070 | D20: Rahila Rashid | E20: 22 | F20: 2395 | G20: 2236 | H20: 0.10148148 | I20: 27 | J20: 1.2272727 | K20: 88.84 | L20: 89.73 | M20: 86 | N20: 87.72 | O20: 88.78 | P20: 92.49 | Q20: 0.2176 | R20: 0.0193 | S20: 0.7631 | T20: 0.0028 | U20: 0.0744 | V20: 0.011 | W20: 0.0496 | X20: 0.6915 | Y20: 0.0496 | Z20: 0.0358 | AA20: 0.0028 | AB20: 0.0138 | AC20: 0.0468 | AD20: 0.0028
A21: MAG7 | B21: Vikram Kumar majhi | C21: S24539 | D21: Haseeb Ur Rehaman | E21: 26 | F21: 3044 | G21: 2740 | H21: 0.15616898 | I21: 30 | J21: 1.1538462 | K21: 86.75 | L21: 86.93 | M21: 85.98 | N21: 86.31 | O21: 82.99 | P21: 90.88 | Q21: 0.1199 | R21: 0.0182 | S21: 0.8619 | T21: 0.0046 | U21: 0.0895 | V21: 0.0106 | W21: 0.0698 | X21: 0.6935 | Y21: 0.0425 | Z21: 0.0349 | AA21: 0.0121 | AB21: 0.0015 | AC21: 0.0228 | AD21: 0
A22: MAG7 | B22: Vikram Kumar majhi | C22: S24536 | D22: Shaik Hassan Mohammed | E22: 26 | F22: 3049 | G22: 2749 | H22: 0.13024306 | I22: 29 | J22: 1.1153846
A24: Campaign | B24: TL | C24: ECN | D24: Advisor | E24: Mandays | F24: Total Attempted | G24: Total Connected | H24: Avg Talk time per day | I24: Assisted Sales ( Highest TT >5min) | J24: SPD/Agent | K24: Quality Score | L24: Listening & Understanding Needs | M24: Product Knowledge and Explanation | N24: Transaction | O24: Acknowledge & Empathise | P24: Language, Tone and Professionalism | Q24: Positive | R24: Negative | S24: Neutral | T24: .escalated | U24: .not_interested_in_buying | V24: .payment_done | W24: .will_buy_self | X24: .positive_intent_needs_follow_up | Y24: .non_material_interaction | Z24: .follow_up_required | AA24: .unresolved | AB24: .partially_resolved | AC24: .resolved | AD24: .threatened_to_escalate | AF24: Correlation | AG24: Correlation | AH24: Correlation | AI24: Correlation | AJ24: Correlation | AK24: Correlation | AL24: Correlation | AM24: Correlation | AN24: Correlation | AO24: Correlation | AP24: Correlation | AQ24: Correlation | AR24: Correlation | AS24: Correlation | AT24: Correlation | AU24: Correlation | AV24: Correlation | AW24: Correlation | AX24: Correlation | AY24: Correlation
A25: Existing | B25: Jithin CJ | C25: S17191 | D25: Mohammed Shoaib A | E25: 26 | F25: 3086 | G25: 2323 | H25: 0.16501157 | I25: 49 | J25: 1.8846154 | K25: 86.37 | L25: 85.84 | M25: 83.71 | N25: 86.88 | O25: 84.06 | P25: 91.53 | Q25: 0.1178 | R25: 0.032 | S25: 0.8502 | T25: 0 | U25: 0.096 | V25: 0.0421 | W25: 0.0236 | X25: 0.6549 | Y25: 0.0505 | Z25: 0.0707 | AA25: 0.0219 | AB25: 0.0067 | AC25: 0.0135 | AD25: 0.0017 | AF25: =CORREL($J$25:$J$31,K25:K31) -> -0.42032489 | AG25: =CORREL($J$25:$J$31,L25:L31) -> -0.35631951 | AH25: =CORREL($J$25:$J$31,M25:M31) -> -0.23061054 | AI25: =CORREL($J$25:$J$31,N25:N31) -> -0.26563777 | AJ25: =CORREL($J$25:$J$31,O25:O31) -> -0.55146086 | AK25: =CORREL($J$25:$J$31,P25:P31) -> -0.53918397 | AL25: =CORREL($J$25:$J$31,Q25:Q31) -> 0.74404647 | AM25: =CORREL($J$25:$J$31,R25:R31) -> 0.23941398 | ... AY25: =CORREL($J$25:$J$31,AD25:AD31) -> 0.076942081
A26: Existing | B26: Jithin CJ | C26: S16986 | D26: Sunil Kumar K | E26: 26 | F26: 4055 | G26: 3307 | H26: 0.13078704 | I26: 54 | J26: 2.0769231 | K26: 85.83 | L26: 85.83 | M26: 85.27 | N26: 86.76 | O26: 78.42 | P26: 91.24 | Q26: 0.1788 | R26: 0.0166 | S26: 0.8046 | T26: 0.0017 | U26: 0.0579 | V26: 0.0215 | W26: 0.106 | X26: 0.707 | Y26: 0.043 | Z26: 0.0182 | AA26: 0 | AB26: 0.0033 | AC26: 0.0298 | AD26: 0.0017
A27: Existing | B27: Jithin CJ | C27: S19751 | D27: Kondareddygari Peddireddy | E27: 22 | F27: 2489 | G27: 2628 | H27: 0.13456019 | I27: 51 | J27: 2.3181818 | K27: 84.37 | L27: 85.93 | M27: 82.01 | N27: 83.73 | O27: 79.71 | P27: 89.87 | Q27: 0.1635 | R27: 0.0285 | S27: 0.808 | T27: 0.0038 | U27: 0.0665 | V27: 0.0209 | W27: 0.1046 | X27: 0.6578 | Y27: 0.0361 | Z27: 0.0494 | AA27: 0.0171 | AB27: 0.0038 | AC27: 0.0361 | AD27: 0.0019
A28: Existing | B28: Jithin CJ | C28: S18572 | D28: Manthesh R | E28: 22 | F28: 2613 | G28: 2467 | H28: 0.14883102 | I28: 36 | J28: 1.6363636 | K28: 87.37 | L28: 86.89 | M28: 85.6 | N28: 86.84 | O28: 85.92 | P28: 91.96 | Q28: 0.1066 | R28: 0.0362 | S28: 0.8571 | T28: 0.002 | U28: 0.0584 | V28: 0.0181 | W28: 0.0845 | X28: 0.6499 | Y28: 0.0523 | Z28: 0.0563 | AA28: 0.0161 | AB28: 0.008 | AC28: 0.0322 | AD28: 0.006
A29: Existing | B29: Jithin CJ | C29: S18945 | D29: Abdul Ayesha Begum | E29: 26 | F29: 4222 | G29: 3136 | H29: 0.1608912 | I29: 32 | J29: 1.2307692 | K29: 85.18 | L29: 85.74 | M29: 82.91 | N29: 84.67 | O29: 80.63 | P29: 91.44 | Q29: 0.0972 | R29: 0.0216 | S29: 0.8812 | T29: 0 | U29: 0.1188 | V29: 0.0162 | W29: 0.0702 | X29: 0.6613 | Y29: 0.0459 | Z29: 0.027 | AA29: 0.0229 | AB29: 0.004 | AC29: 0.0175 | AD29: 0
A30: Existing | B30: Jithin CJ | C30: S18581 | D30: Vivek Kumar | E30: 15 | F30: 1680 | G30: 1539 | H30: 0.2052662 | I30: 18 | J30: 1.2 | K30: 90.15 | L30: 90.1 | M30: 86.85 | N30: 90.4 | O30: 90.83 | P30: 93.54 | Q30: 0.1341 | R30: 0.0171 | S30: 0.8488 | T30: 0 | U30: 0.1 | V30: 0.0122 | W30: 0.0512 | X30: 0.7659 | Y30: 0.0659 | Z30: 0 | AA30: 0 | AB30: 0 | AC30: 0.0049 | AD30: 0
A31: Existing | B31: Jithin CJ | C31: S13366 | D31: Priyanka Hanumappa Nagaral | E31: 24 | F31: 3152 | G31: 2844 | H31: 0.15895833 | I31: 31 | J31: 1.2916667 | K31: 84.81 | L31: 85.04 | M31: 82.37 | N31: 83.84 | O31: 82.39 | P31: 90.4 | Q31: 0.0957 | R31: 0.0262 | S31: 0.8781 | T31: 0.0031 | U31: 0.1003 | V31: 0.0139 | W31: 0.0417 | X31: 0.6759 | Y31: 0.071 | Z31: 0.0478 | AA31: 0.0108 | AB31: 0.0062 | AC31: 0.0201 | AD31: 0.0046
A33: Campaign | B33: TL | C33: ECN | D33: Advisor | E33: Mandays | F33: Total Attempted | G33: Total Connected | H33: Avg Talk time per day | I33: Assisted Sales ( Highest TT >5min) | J33: SPD/Agent | K33: Quality Score | L33: Listening & Understanding Needs | M33: Product Knowledge and Explanation | N33: Transaction | O33: Acknowledge & Empathise | P33: Language, Tone and Professionalism | Q33: Positive | R33: Negative | S33: Neutral | T33: .escalated | U33: .not_interested_in_buying | V33: .payment_done | W33: .will_buy_self | X33: .positive_intent_needs_follow_up | Y33: .non_material_interaction | Z33: .follow_up_required | AA33: .unresolved | AB33: .partially_resolved | AC33: .resolved | AD33: .threatened_to_escalate | AF33: Correlation | AG33: Correlation | AH33: Correlation | AI33: Correlation | AJ33: Correlation | AK33: Correlation | AL33: Correlation | AM33: Correlation | AN33: Correlation | AO33: Correlation | AP33: Correlation | AQ33: Correlation | AR33: Correlation | AS33: Correlation | AT33: Correlation | AU33: Correlation | AV33: Correlation | AW33: Correlation | AX33: Correlation | AY33: Correlation
A34: Non Existing | B34: Varun Raj | C34: S19746 | D34: Chandana M | E34: 1 | F34: 170 | G34: 106 | H34: 0.19512731 | I34: 7 | J34: 7 | K34: 79.68 | L34: 81.94 | M34: 77.42 | N34: 74.84 | O34: 78.39 | P34: 85.81 | Q34: 0.0313 | R34: 0.0938 | S34: 0.875 | T34: 0 | U34: 0 | V34: 0 | W34: 0 | X34: 0 | Y34: 0 | Z34: 0.5938 | AA34: 0.3125 | AB34: 0 | AC34: 0.0938 | AD34: 0 | AF34: =CORREL($J$34:$J$52,K34:K52) -> -0.49170818 | AG34: =CORREL($J$34:$J$52,L34:L52) -> -0.33270706 | AH34: =CORREL($J$34:$J$52,M34:M52) -> -0.38944175 | AI34: =CORREL($J$34:$J$52,N34:N52) -> -0.61987198 | AJ34: =CORREL($J$34:$J$52,O34:O52) -> -0.51072848 | AK34: =CORREL($J$34:$J$52,P34:P52) -> -0.51760645 | AL34: =CORREL($J$34:$J$52,Q34:Q52) -> -0.3981439 | AM34: =CORREL($J$34:$J$52,R34:R52) -> 0.80914921 | ... AY34: =CORREL($J$34:$J$52,AD34:AD52) -> -0.3112696
A35: Non Existing | B35: Varun Raj | C35: S13357 | D35: Smrutiranjan Biswal | E35: 19 | F35: 2537 | G35: 1929 | H35: 0.19224537 | I35: 33 | J35: 1.7368421 | K35: 89.26 | L35: 89.63 | M35: 87.25 | N35: 89.01 | O35: 86.09 | P35: 94.05 | Q35: 0.1297 | R35: 0.0144 | S35: 0.8559 | T35: 0.0036 | U35: 0.0919 | V35: 0.0234 | W35: 0.0829 | X35: 0.6414 | Y35: 0.0919 | Z35: 0.0324 | AA35: 0.009 | AB35: 0 | AC35: 0.0234 | AD35: 0
A36: Non Existing | B36: Varun Raj | C36: S24538 | D36: Kamal Hassan Laskar | E36: 27 | F36: 4137 | G36: 2914 | H36: 0.19666667 | I36: 47 | J36: 1.7407407 | K36: 89.58 | L36: 89.73 | M36: 87.16 | N36: 88.67 | O36: 89.22 | P36: 93.59 | Q36: 0.1363 | R36: 0.0249 | S36: 0.8388 | T36: 0.0052 | U36: 0.0983 | V36: 0.0118 | W36: 0.0511 | X36: 0.6815 | Y36: 0.0485 | Z36: 0.0472 | AA36: 0.0092 | AB36: 0.0026 | AC36: 0.0183 | AD36: 0.0052
A37: Non Existing | B37: Ashil Simon | C37: S18566 | D37: Chethan C | E37: 25 | F37: 2350 | G37: 1851 | H37: 0.20653935 | I37: 33 | J37: 1.32 | K37: 90.08 | L37: 90.05 | M37: 88.46 | N37: 89.26 | O37: 89.28 | P37: 93.52 | Q37: 0.1082 | R37: 0.0242 | S37: 0.8675 | T37: 0 | U37: 0.063 | V37: 0.0129 | W37: 0.0388 | X37: 0.7221 | Y37: 0.0468 | Z37: 0.0549 | AA37: 0.0081 | AB37: 0.0129 | AC37: 0.0242 | AD37: 0.0048
A38: Non Existing | B38: Varun Raj | C38: S12909 | D38: Praneeth Sanil | E38: 22 | F38: 4071 | G38: 3068 | H38: 0.18224537 | I38: 49 | J38: 2.2272727 | K38: 83.83 | L38: 84.41 | M38: 82.41 | N38: 84.43 | O38: 80.28 | P38: 87.23 | Q38: 0.1406 | R38: 0.0106 | S38: 0.8488 | T38: 0 | U38: 0.0597 | V38: 0.0106 | W38: 0.061 | X38: 0.6525 | Y38: 0.0597 | Z38: 0.0676 | AA38: 0.0225 | AB38: 0.0066 | AC38: 0.0438 | AD38: 0
A39: Non Existing | B39: Ashil Simon | C39: S23771 | D39: Syed Zaiduddin | E39: 23 | F39: 2454 | G39: 2015 | H39: 0.12908565 | I39: 31 | J39: 1.3478261 | K39: 89.4 | L39: 88.8 | M39: 87.72 | N39: 88.4 | O39: 88.95 | P39: 93.47 | Q39: 0.1172 | R39: 0.0137 | S39: 0.8691 | T39: 0 | U39: 0.1191 | V39: 0.0176 | W39: 0.0293 | X39: 0.6406 | Y39: 0.0527 | Z39: 0.0664 | AA39: 0.0195 | AB39: 0.002 | AC39: 0.0234 | AD39: 0
A40: Non Existing | B40: Varun Raj | C40: S24831 | D40: R Maria Reena | E40: 27 | F40: 5099 | G40: 3719 | H40: 0.20372685 | I40: 45 | J40: 1.6666667 | K40: 87.55 | L40: 87.62 | M40: 84.15 | N40: 86.91 | O40: 88.6 | P40: 91.39 | Q40: 0.0913 | R40: 0.0181 | S40: 0.8907 | T40: 0.002 | U40: 0.0802 | V40: 0.0281 | W40: 0.0331 | X40: 0.7292 | Y40: 0.0381 | Z40: 0.0502 | AA40: 0.006 | AB40: 0.003 | AC40: 0.0191 | AD40: 0.001
A41: Non Existing | B41: Ashil Simon | C41: S17518 | D41: Santosh Jeruni Siddi | E41: 24 | F41: 3621 | G41: 3049 | H41: 0.18163194 | I41: 43 | J41: 1.7916667 | K41: 87.07 | L41: 86.86 | M41: 84.77 | N41: 85.6 | O41: 86.88 | P41: 91.83 | Q41: 0.0858 | R41: 0.0275 | S41: 0.8867 | T41: 0.0023 | U41: 0.1865 | V41: 0.0206 | W41: 0.0549 | X41: 0.587 | Y41: 0.0732 | Z41: 0.0275 | AA41: 0.0137 | AB41: 0.0011 | AC41: 0.0229 | AD41: 0.0011
A42: Non Existing | B42: Ashil Simon | C42: S17198 | D42: Ali Hussain Musthaq | E42: 25 | F42: 4377 | G42: 3036 | H42: 0.18703704 | I42: 35 | J42: 1.4 | K42: 88.2 | L42: 88.89 | M42: 86.41 | N42: 87.04 | O42: 85.56 | P42: 92.89 | Q42: 0.1123 | R42: 0.0205 | S42: 0.8671 | T42: 0.0041 | U42: 0.1123 | V42: 0.0041 | W42: 0.0808 | X42: 0.6616 | Y42: 0.0507 | Z42: 0.0356 | AA42: 0.0055 | AB42: 0.0068 | AC42: 0.0219 | AD42: 0.0014
A43: Non Existing | B43: Varun Raj | C43: S18919 | D43: Arfath Abbas | E43: 24 | F43: 3746 | G43: 2887 | H43: 0.13092593 | I43: 40 | J43: 1.6666667 | K43: 88.05 | L43: 87.68 | M43: 84.58 | N43: 87.18 | O43: 88.29 | P43: 93.37 | Q43: 0.1227 | R43: 0.0282 | S43: 0.8491 | T43: 0.0014 | U43: 0.134 | V43: 0.0339 | W43: 0.0564 | X43: 0.6375 | Y43: 0.0409 | Z43: 0.0423 | AA43: 0.0254 | AB43: 0.0028 | AC43: 0.0141 | AD43: 0
...

Sheet Sheet8
D1: agent_id | E1: skill | F1: Average of overall_percentage | G1: Average of Listening & Understanding Needs | H1: Average of Product Knowledge and Explanation | I1: Average of Transaction | J1: Average of Acknowledge & Empathise | K1: Average of Language, Tone and Professionalism | L1: #VALUE! | M1: Sum of .negative_sentiment_count | N1: Sum of .neutral_sentiment_count | O1: .escalated | P1: .not_interested_in_buying | Q1: .payment_done | R1: .will_buy_self | S1: .positive_intent_needs_follow_up | T1: .non_material_interaction | U1: .follow_up_required | V1: .unresolved | W1: .partially_resolved | X1: .resolved | Y1: .threatened_to_escalate
C2: {=XLOOKUP(D2,'Agent Index'!B:B,'Agent Index'!C:C)} -> Abdul Ayesha Begum | D2: abdul.begum_scale_blr@acko.com | E2: Existing - Rest of the Floor | F2: 85.18 | G2: 85.74 | H2: 82.91 | I2: 84.67 | J2: 80.63 | K2: 91.44 | L2: 0.0972 | M2: 0.0216 | N2: 0.8812 | O2: 0 | P2: 0.1188 | Q2: 0.0162 | R2: 0.0702 | S2: 0.6613 | T2: 0.0459 | U2: 0.027 | V2: 0.0229 | W2: 0.004 | X2: 0.0175 | Y2: 0
C3: {=XLOOKUP(D3,'Agent Index'!B:B,'Agent Index'!C:C)} -> Abhishek Chandra | D3: abhishek.chandra_scale_blr@acko.com | E3: Inbound | F3: 90.58 | G3: 90.65 | H3: 88.39 | I3: 89.96 | J3: 90.15 | K3: 94.15 | L3: 0.1703 | M3: 0.038 | N3: 0.7917 | O3: 0.0054 | P3: 0.0725 | Q3: 0.0435 | R3: 0.0725 | S3: 0.6014 | T3: 0.0797 | U3: 0.0435 | V3: 0.0163 | W3: 0.0072 | X3: 0.0471 | Y3: 0.0054
C4: {=XLOOKUP(D4,'Agent Index'!B:B,'Agent Index'!C:C)} -> Afreen Saba | D4: afreen.saba_scale_blr@acko.com | E4: Porting | F4: 87.04 | G4: 86.94 | H4: 85.22 | I4: 85.85 | J4: 86.78 | K4: 90.69 | L4: 0.1832 | M4: 0.0429 | N4: 0.7739 | O4: 0.0033 | P4: 0.071 | Q4: 0.0512 | R4: 0.0792 | S4: 0.6634 | T4: 0.0314 | U4: 0.0561 | V4: 0.005 | W4: 0.005 | X4: 0.0297 | Y4: 0.005
C5: {=XLOOKUP(D5,'Agent Index'!B:B,'Agent Index'!C:C)} -> Mohammed Suhail | D5: alfiya_scale_blr@acko.com | E5: Existing - Mag7 New Batch Old Advisor | F5: 88.27 | G5: 87.29 | H5: 85.98 | I5: 87.39 | J5: 88.18 | K5: 93.1 | L5: 0.1289 | M5: 0.0264 | N5: 0.8447 | O5: 0.0062 | P5: 0.0932 | Q5: 0.0186 | R5: 0.0714 | S5: 0.6941 | T5: 0.0233 | U5: 0.0606 | V5: 0.0093 | W5: 0.0016 | X5: 0.014 | Y5: 0.0062
C6: {=XLOOKUP(D6,'Agent Index'!B:B,'Agent Index'!C:C)} -> Ali Hussain Musthaq | D6: ali.musthaq_scale_blr@acko.com | E6: Non-Existing | F6: 88.2 | G6: 88.89 | H6: 86.41 | I6: 87.04 | J6: 85.56 | K6: 92.89 | L6: 0.1123 | M6: 0.0205 | N6: 0.8671 | O6: 0.0041 | P6: 0.1123 | Q6: 0.0041 | R6: 0.0808 | S6: 0.6616 | T6: 0.0507 | U6: 0.0356 | V6: 0.0055 | W6: 0.0068 | X6: 0.0219 | Y6: 0.0014
C7: {=XLOOKUP(D7,'Agent Index'!B:B,'Agent Index'!C:C)} -> Arfath Abbas | D7: arfath.abbas_scale_blr@acko.com | E7: Non-Existing | F7: 88.05 | G7: 87.68 | H7: 84.58 | I7: 87.18 | J7: 88.29 | K7: 93.37 | L7: 0.1227 | M7: 0.0282 | N7: 0.8491 | O7: 0.0014 | P7: 0.134 | Q7: 0.0339 | R7: 0.0564 | S7: 0.6375 | T7: 0.0409 | U7: 0.0423 | V7: 0.0254 | W7: 0.0028 | X7: 0.0141 | Y7: 0
C8: {=XLOOKUP(D8,'Agent Index'!B:B,'Agent Index'!C:C)} -> Athiqa Kousher | D8: athiqa.kousher_scale_blr@acko.com | E8: Outbound | F8: 87.7 | G8: 87.85 | H8: 83.04 | I8: 87.09 | J8: 88.55 | K8: 93.31 | L8: 0.0901 | M8: 0.0245 | N8: 0.8855 | O8: 0.0039 | P8: 0.1493 | Q8: 0.0142 | R8: 0.0347 | S8: 0.722 | T8: 0.0553 | U8: 0 | V8: 0 | W8: 0 | X8: 0.0077 | Y8: 0.0026
C9: {=XLOOKUP(D9,'Agent Index'!B:B,'Agent Index'!C:C)} | D9: attikka.danish_scale_blr@acko.com | E9: Renewals | F9: 86.97 | G9: 88.11 | H9: 82.2 | I9: 87.72 | J9: 85.02 | K9: 92.36 | L9: 0.1968 | M9: 0.0663 | N9: 0.7369 | O9: 0.008 | P9: 0.0763 | Q9: 0.0622 | R9: 0.2229 | S9: 0.4357 | T9: 0.0562 | U9: 0.0562 | V9: 0.004 | W9: 0.006 | X9: 0.0602 | Y9: 0.0141
C10: {=XLOOKUP(D10,'Agent Index'!B:B,'Agent Index'!C:C)} -> Bellary Jaffer Sadiq | D10: bellary.sadiq_scale_blr@acko.com | E10: Inbound | F10: 88.38 | G10: 89.4 | H10: 85.44 | I10: 87.28 | J10: 88.59 | K10: 91.93 | L10: 0.1486 | M10: 0.044 | N10: 0.8073 | O10: 0.011 | P10: 0.0532 | Q10: 0.022 | R10: 0.0624 | S10: 0.6771 | T10: 0.055 | U10: 0.0404 | V10: 0.0165 | W10: 0.0055 | X10: 0.044 | Y10: 0.0037
C11: {=XLOOKUP(D11,'Agent Index'!B:B,'Agent Index'!C:C)} | D11: bojamma.ka_scale_blr@acko.com | E11: Renewals | F11: 87.85 | G11: 88.46 | H11: 83.89 | I11: 87.31 | J11: 88.13 | K11: 92.48 | L11: 0.1614 | M11: 0.0568 | N11: 0.7818 | O11: 0.012 | P11: 0.0792 | Q11: 0.0478 | R11: 0.1839 | S11: 0.5306 | T11: 0.0987 | U11: 0.0015 | V11: 0 | W11: 0.003 | X11: 0.0299 | Y11: 0.0075
C12: {=XLOOKUP(D12,'Agent Index'!B:B,'Agent Index'!C:C)} -> Chandana M | D12: chandana.m_scale_blr@acko.com | E12: Non-Existing | F12: 79.68 | G12: 81.94 | H12: 77.42 | I12: 74.84 | J12: 78.39 | K12: 85.81 | L12: 0.0313 | M12: 0.0938 | N12: 0.875 | O12: 0 | P12: 0 | Q12: 0 | R12: 0 | S12: 0 | T12: 0 | U12: 0.5938 | V12: 0.3125 | W12: 0 | X12: 0.0938 | Y12: 0
C13: {=XLOOKUP(D13,'Agent Index'!B:B,'Agent Index'!C:C)} -> Chethan C | D13: chethan.c_scale_blr@acko.com | E13: Non-Existing | F13: 90.08 | G13: 90.05 | H13: 88.46 | I13: 89.26 | J13: 89.28 | K13: 93.52 | L13: 0.1082 | M13: 0.0242 | N13: 0.8675 | O13: 0 | P13: 0.063 | Q13: 0.0129 | R13: 0.0388 | S13: 0.7221 | T13: 0.0468 | U13: 0.0549 | V13: 0.0081 | W13: 0.0129 | X13: 0.0242 | Y13: 0.0048
... C61: {=XLOOKUP(D61,'Agent Index'!B:B,'Agent Index'!C:C)} -> Vivek Kumar | D61: vivek.kumar1_scale_blr@acko.com | E61: Existing - Rest of the Floor | F61: 90.15 | G61: 90.1 | H61: 86.85 | I61: 90.4 | J61: 90.83 | K61: 93.54 | L61: 0.1341 | M61: 0.0171 | N61: 0.8488 | O61: 0 | P61: 0.1 | Q61: 0.0122 | R61: 0.0512 | S61: 0.7659 | T61: 0.0659 | U61: 0 | V61: 0 | W61: 0 | X61: 0.0049 | Y61: 0
C62: {=XLOOKUP(D62,'Agent Index'!B:B,'Agent Index'!C:C)} -> #N/A | D62: Grand Total | F62: 87.12 | G62: 87.35 | H62: 84.79 | I62: 86.71 | J62: 85.33 | K62: 91.82 | L62: 0.1302 | M62: 0.0292 | N62: 0.8406 | O62: 0.0038 | P62: 0.1061 | Q62: 0.0233 | R62: 0.0625 | S62: 0.6447 | T62: 0.0546 | U62: 0.0435 | V62: 0.0136 | W62: 0.004 | X62: 0.0282 | Y62: 0.0026

Sheet Life
A1: Campaign | B1: Manager | C1: ECN | D1: Advisor | E1: Mandays | F1: Total Attempted | G1: Total Connected | H1: Avg Talk time per day | I1: Assisted Sales ( Highest TT >5min) | J1: SPD/Agent | K1: Helpfullness Score | L1: Quality Bucket | M1: Correlation | O1: Listening & Understanding Needs | P1: Acknowledge & Empathise | Q1: Language, Tone and Professionalism | R1: Transaction | S1: Correlation | T1: Correlation | U1: Correlation | V1: Correlation
A2: D2C | B2: Rajni Kwatra | C2: S17652 | D2: Ayesha Siddiqa | E2: 27 | F2: 8439 | G2: 4786 | H2: 0.17105324 | I2: 33 | J2: =I2/E2 -> 1.2222222 | K2: 87.92 | L2: =IF(K2<80,"L80",IF(K2<=85,"81-85",IF(K2<=90,"85-90",IF(K2<=95,"91-95","G95%")))) -> 85-90 | M2: =CORREL(K2:K13,J2:J13) -> 0.34794863 | O2: 86.946232 | P2: 85.729235 | Q2: 91.136846 | R2: 87.512466 | S2: =CORREL(O2:O13,$J$2:$J$13) -> 0.33691225 | T2: =CORREL(P2:P13,$J$2:$J$13) -> 0.21901892 | U2: =CORREL(Q2:Q13,$J$2:$J$13) -> 0.40176049 | V2: =CORREL(R2:R13,$J$2:$J$13) -> 0.30753405
A3: D2C | B3: Rajni Kwatra | C3: S17658 | D3: Fakkiresh Kalaghatagi | E3: 24 | F3: 5572 | G3: 3895 | H3: 0.18021991 | I3: 31 | J3: =I3/E3 -> 1.2916667 | K3: 89.2 | L3: =IF(K3<80,"L80",IF(K3<=85,"81-85",IF(K3<=90,"85-90",IF(K3<=95,"91-95","G95%")))) -> 85-90 | O3: 88.583458 | P3: 87.285111 | Q3: 90.786815 | R3: 89.779354
A4: D2C | B4: Rajni Kwatra | C4: S24833 | D4: Gayathre B | E4: 27 | F4: 6846 | G4: 4179 | H4: 0.19644676 | I4: 51 | J4: =I4/E4 -> 1.8888889 | K4: 87.29 | L4: =IF(K4<80,"L80",IF(K4<=85,"81-85",IF(K4<=90,"85-90",IF(K4<=95,"91-95","G95%")))) -> 85-90 | O4: 86.123551 | P4: 83.979128 | Q4: 90.84554 | R4: 87.550399
A5: D2C | B5: Rajni Kwatra | C5: S24839 | D5: Jaishree Thapa | E5: 25 | F5: 7141 | G5: 5176 | H5: 0.16962963 | I5: 36 | J5: =I5/E5 -> 1.44 | K5: 87.24 | L5: =IF(K5<80,"L80",IF(K5<=85,"81-85",IF(K5<=90,"85-90",IF(K5<=95,"91-95","G95%")))) -> 85-90 | O5: 85.685012 | P5: 85.985712 | Q5: 90.475278 | R5: 86.636774
A6: D2C | B6: Rajni Kwatra | C6: S24837 | D6: Khan Ayaz | E6: 26 | F6: 6233 | G6: 4398 | H6: 0.18071759 | I6: 26 | J6: =I6/E6 -> 1 | K6: 88.63 | L6: =IF(K6<80,"L80",IF(K6<=85,"81-85",IF(K6<=90,"85-90",IF(K6<=95,"91-95","G95%")))) -> 85-90 | O6: 87.453007 | P6: 84.476277 | Q6: 92.39197 | R6: 89.279595
A7: D2C | B7: Rajni Kwatra | C7: S20979 | D7: Muskan Taj | E7: 27 | F7: 6015 | G7: 4523 | H7: 0.14780093 | I7: 38 | J7: =I7/E7 -> 1.4074074 | K7: 88.75 | L7: =IF(K7<80,"L80",IF(K7<=85,"81-85",IF(K7<=90,"85-90",IF(K7<=95,"91-95","G95%")))) -> 85-90 | O7: 88.439844 | P7: 83.691068 | Q7: 91.916708 | R7: 89.840535
A8: D2C | B8: Rajni Kwatra | C8: S20982 | D8: Onkar Suresh Bhagoji | E8: 21 | F8: 4361 | G8: 3150 | H8: 0.19069444 | I8: 44 | J8: =I8/E8 -> 2.0952381 | K8: 90.96 | L8: =IF(K8<80,"L80",IF(K8<=85,"81-85",IF(K8<=90,"85-90",IF(K8<=95,"91-95","G95%")))) -> 91-95 | O8: 89.873782 | P8: 87.635195 | Q8: 93.551413 | R8: 91.9535
A9: D2C | B9: Rajni Kwatra | C9: S19317 | D9: Pikal Das | E9: 27 | F9: 4737 | G9: 3580 | H9: 0.18010417 | I9: 50 | J9: =I9/E9 -> 1.8518519 | K9: 90.05 | L9: =IF(K9<80,"L80",IF(K9<=85,"81-85",IF(K9<=90,"85-90",IF(K9<=95,"91-95","G95%")))) -> 91-95 | O9: 89.20578 | P9: 88.011966 | Q9: 92.717276 | R9: 89.960842
A10: D2C | B10: Rajni Kwatra | C10: S18188 | D10: Roshan R | E10: 27 | F10: 5680 | G10: 4153 | H10: 0.13675926 | I10: 29 | J10: =I10/E10 -> 1.0740741 | K10: 89.61 | L10: =IF(K10<80,"L80",IF(K10<=85,"81-85",IF(K10<=90,"85-90",IF(K10<=95,"91-95","G95%")))) -> 85-90 | O10: 88.727713 | P10: 87.426669 | Q10: 92.279552 | R10: 89.575606
A11: D2C | B11: Rajni Kwatra | C11: S17649 | D11: Saniya S | E11: 4 | F11: 982 | G11: 587 | H11: 0.088020833 | I11: 7 | J11: =I11/E11 -> 1.75 | K11: 88.87 | L11: =IF(K11<80,"L80",IF(K11<=85,"81-85",IF(K11<=90,"85-90",IF(K11<=95,"91-95","G95%")))) -> 85-90 | O11: 89.12619 | P11: 84.654762 | Q11: 93.506349 | R11: 88.190476
A12: D2C | B12: Rajni Kwatra | C12: S19635 | D12: Sourav D S | E12: 27 | F12: 6700 | G12: 4598 | H12: 0.15486111 | I12: 39 | J12: =I12/E12 -> 1.4444444 | K12: 88.73 | L12: =IF(K12<80,"L80",IF(K12<=85,"81-85",IF(K12<=90,"85-90",IF(K12<=95,"91-95","G95%")))) -> 85-90 | O12: 88.152508 | P12: 83.591534 | Q12: 92.512331 | R12: 89.537057
A13: D2C | B13: Rajni Kwatra | C13: S20702 | D13: Umme Hani | E13: 16 | F13: 5694 | G13: 3863 | H13: 0.14824074 | I13: 20 | J13: =I13/E13 -> 1.25 | K13: 85.17 | L13: =IF(K13<80,"L80",IF(K13<=85,"81-85",IF(K13<=90,"85-90",IF(K13<=95,"91-95","G95%")))) -> 85-90 | O13: 83.246542 | P13: 82.772132 | Q13: 89.44341 | R13: 84.883466

Sheet CS
A1: LOB | B1: Team Leader | C1: Emp ID | D1: Advisor | E1: Mandays | F1: Total Attempted | G1: Total Answered | H1: Average of Talk_Duration | I1: CES Score | J1: Quality | K1: Percentage Positive
A2: Auto | B2: Kunuku Prasant Teja | C2: S5049 | D2: Fazluddin 1 | E2: 24 | F2: 568 | G2: 534 | H2: 0.0039814815 | I2: 0.8218
A3: Auto | B3: Akshay Kumar | C3: S5121 | D3: Afthab Sayyad | E3: 19 | F3: 1103 | G3: 669 | H3: 0.00079861111 | I3: 0.7976
A4: Auto | B4: Akshay Kumar | C4: S9989 | D4: Karthik Rao | E4: 20 | F4: 1394 | G4: 813 | H4: 0.0011111111 | I4: 0.7917
A5: Auto | B5: Akshay Kumar | C5: S11631 | D5: Supriya O | E5: 26 | F5: 1947 | G5: 1019 | H5: 0.0010185185 | I5: 0.9538
A6: Auto | B6: Akshay Kumar | C6: S11632 | D6: Syed Mouin | E6: 26 | F6: 1547 | G6: 957 | H6: 0.00097222222 | I6: 0.7077
A7: Auto | B7: Akshay Kumar | C7: S11932 | D7: Deepika R Shankar | E7: 15.5 | F7: 888 | G7: 435 | H7: 0.00087962963 | I7: 0.9298
A8: Auto | B8: Kunuku Prasant Teja | C8: S11954 | D8: Mohammed Ruman | E8: 22.5 | F8: 298 | G8: 256 | H8: 0.0027083333 | I8: 0.32
A9: Auto | B9: Kunuku Prasant Teja | C9: S13025 | D9: Hajeera Begum | E9: 26 | F9: 1034 | G9: 787 | H9: 0.0046643519 | I9: 0.525
A10: Auto | B10: Kunuku Prasant Teja | C10: S14298 | D10: Raziqha Zeeshan | E10: 18 | F10: 439 | G10: 330 | H10: 0.0028819444 | I10: 0.619
A11: Auto | B11: Kunuku Prasant Teja | C11: S14364 | D11: Mohammed Arfath | E11: 24 | F11: 439 | G11: 361 | H11: 0.0030902778 | I11: 0.8
A12: Auto | B12: Akshay Kumar | C12: S14547 | D12: Shadan Rahman | E12: 23 | F12: 1453 | G12: 997 | H12: 0.0021064815 | I12: 0.6667
A13: Auto | B13: Akshay Kumar | C13: S14684 | D13: Tabassum Banu | E13: 21 | F13: 734 | G13: 431 | H13: 0.0010648148 | I13: 1
... A121: Auto & Health | B121: Amit Jha | C121: S25442 | D121: Mehak Fathima | E121: 22 | F121: 650 | G121: 550 | H121: 0.003587963 | I121: 0.4667
A122: Embedded & Electronics | B122: Amandeep Singh | C122: 801529 | D122: Simranjeet Kaur | E122: 24 | F122: 1526 | G122: 1234 | H122: 0.0027777778 | I122: 0.7105
A123: Embedded & Electronics | B123: Amandeep Singh | C123: 802546 | D123: Gurpreet Kaur | E123: 24 | F123: 1991 | G123: 1317 | H123: 0.0021990741 | I123: 0.7333
A124: Embedded & Electronics | B124: Amandeep Singh | C124: 804327 | D124: Anshita Sharma | E124: 23 | F124: 1388 | G124: 858 | H124: 0.0035069444 | I124: 0.8462
A125: Embedded & Electronics | B125: Amandeep Singh | C125: 804663 | D125: Rania Khokhar | E125: 24 | F125: 1756 | G125: 1304 | H125: 0.0031481481 | I125: 0.8065
A126: Embedded & Electronics | B126: Amandeep Singh | C126: 804666 | D126: Raghuraj Raj | E126: 20 | F126: 1526 | G126: 1388 | H126: 0.0034375 | I126: 0.8955
A127: Embedded & Electronics | B127: Amandeep Singh | C127: 804969 | D127: Mahi Kumar | E127: 26 | F127: 2007 | G127: 1721 | H127: 0.0025810185 | I127: 0.9306
A128: Embedded & Electronics | B128: Amandeep Singh | C128: 805239 | D128: pushpinderjit kaur | E128: 5 | F128: 325 | G128: 285 | H128: 0.0034837963 | I128: ~
A129: Embedded & Electronics | B129: Amandeep Singh | C129: 805394 | D129: Sunidhi Sharma | E129: 24 | F129: 2319 | G129: 2116 | H129: 0.002025463 | I129: 0.7344
A130: Embedded & Electronics | B130: Amandeep Singh | C130: 805780 | D130: Mehak Dhalla | E130: 11 | F130: 736 | G130: 576 | H130: 0.0029513889 | I130: 0.7143
A131: Embedded & Electronics | B131: Amandeep Singh | C131: 805966 | D131: Aditi Kandial | E131: 21 | F131: 1326 | G131: 1097 | H131: 0.0037384259 | I131: 0.7179
A132: Embedded & Electronics | B132: Amandeep Singh | C132: 806251 | D132: Manroop Mehra | E132: 25 | F132: 1614 | G132: 1401 | H132: 0.0044328704 | I132: 0.9
A133: Embedded & Electronics | B133: Amandeep Singh | C133: 806479 | D133: Akansha Sareen | E133: 24 | F133: 1260 | G133: 1164 | H133: 0.0037731481 | I133: 0.7
A134: Embedded & Electronics | B134: Amandeep Singh | C134: 806481 | D134: Shamsher Singh | E134: 26 | F134: 1197 | G134: 1084 | H134: 0.002974537 | I134: 1
A135: Embedded & Electronics | B135: Amandeep Singh | C135: 806482 | D135: Bhumika Bharadwaj | E135: 24 | F135: 1303 | G135: 1217 | H135: 0.0037152778 | I135: 0.75
A136: Embedded & Electronics | B136: Amandeep Singh | C136: 806551 | D136: Chetna 1 | E136: 19 | F136: 625 | G136: 565 | H136: 0.003587963 | I136: 0.84
A137: Embedded & Electronics | B137: Amandeep Singh | C137: 806941 | D137: Aman deep Kaur | E137: 22 | F137: 687 | G137: 579 | H137: 0.0052546296 | I137: ~
A138: Embedded & Electronics | B138: Amandeep Singh | C138: 806942 | D138: Muskan Sharma | E138: 8 | F138: 228 | G138: 186 | H138: 0.0051157407 | I138: ~
A139: Embedded & Electronics | B139: Ramanpreet Singh | C139: 309818 | D139: Priya Kumari | E139: 24 | F139: 1631 | G139: 987 | H139: 0.0026736111 | I139: 1
A140: Embedded & Electronics | B140: Ramanpreet Singh | C140: 800003 | D140: Harsimranjeet Kaur | E140: 22 | F140: 886 | G140: 661 | H140: 0.0021296296 | I140: 0.4338
A141: Embedded & Electronics | B141: Ramanpreet Singh | C141: 800520 | D141: Sahil Sharma | E141: 23 | F141: 1235 | G141: 886 | H141: 0.0022916667 | I141: 0.6849
A142: Embedded & Electronics | B142: Ramanpreet Singh | C142: 800521 | D142: Devika nagpal | E142: 0 | F142: 0 | G142: 0 | H142: ~ | I142: ~
A143: Embedded & Electronics | B143: Ramanpreet Singh | C143: 801217 | D143: Divjot Kaur | E143: 20 | F143: 1770 | G143: 1348 | H143: 0.0023842593 | I143: 0.7576
A144: Embedded & Electronics | B144: Ramanpreet Singh | C144: 801219 | D144: Aryan Bhatia | E144: 7 | F144: 313 | G144: 213 | H144: 0.0015625 | I144: ~
A145: Embedded & Electronics | B145: Ramanpreet Singh | C145: 802092 | D145: Rashmi S | E145: 22 | F145: 1556 | G145: 1216 | H145: 0.0028356481 | I145: 0.6034
A146: Embedded & Electronics | B146: Ramanpreet Singh | C146: 802439 | D146: Sukhmeet Kaur | E146: 23 | F146: 1349 | G146: 1043 | H146: 0.002650463 | I146: 0.8537
A147: Embedded & Electronics | B147: Ramanpreet Singh | C147: 802440 | D147: Kumkum Sharma | E147: 25 | F147: 1186 | G147: 986 | H147: 0.0023032407 | I147: 0.5789
...
